/var/spool/slurmd/job78104/slurm_script: line 10: data: command not found
Using dropout 0.5
Epoch 1/20
----------
Traceback (most recent call last):
  File "train_CNN.py", line 115, in <module>
    main()
  File "train_CNN.py", line 61, in main
    outputs = model(image)
  File "/public/dengzhijian/miniconda3/envs/dfs/lib/python3.6/site-packages/torch/nn/modules/module.py", line 727, in _call_impl
    result = self.forward(*input, **kwargs)
  File "/public/dengzhijian/miniconda3/envs/dfs/lib/python3.6/site-packages/torch/nn/parallel/data_parallel.py", line 159, in forward
    return self.module(*inputs[0], **kwargs[0])
  File "/public/dengzhijian/miniconda3/envs/dfs/lib/python3.6/site-packages/torch/nn/modules/module.py", line 727, in _call_impl
    result = self.forward(*input, **kwargs)
  File "/public/dengzhijian/Deepfake-Detection-master/network/models.py", line 125, in forward
    x = self.model(x)
  File "/public/dengzhijian/miniconda3/envs/dfs/lib/python3.6/site-packages/torch/nn/modules/module.py", line 727, in _call_impl
    result = self.forward(*input, **kwargs)
  File "/public/dengzhijian/Deepfake-Detection-master/network/xception.py", line 208, in forward
    x = self.features(input)
  File "/public/dengzhijian/Deepfake-Detection-master/network/xception.py", line 181, in features
    x = self.block4(x)
  File "/public/dengzhijian/miniconda3/envs/dfs/lib/python3.6/site-packages/torch/nn/modules/module.py", line 727, in _call_impl
    result = self.forward(*input, **kwargs)
  File "/public/dengzhijian/Deepfake-Detection-master/network/xception.py", line 100, in forward
    x = self.rep(inp)
  File "/public/dengzhijian/miniconda3/envs/dfs/lib/python3.6/site-packages/torch/nn/modules/module.py", line 727, in _call_impl
    result = self.forward(*input, **kwargs)
  File "/public/dengzhijian/miniconda3/envs/dfs/lib/python3.6/site-packages/torch/nn/modules/container.py", line 117, in forward
    input = module(input)
  File "/public/dengzhijian/miniconda3/envs/dfs/lib/python3.6/site-packages/torch/nn/modules/module.py", line 727, in _call_impl
    result = self.forward(*input, **kwargs)
  File "/public/dengzhijian/Deepfake-Detection-master/network/xception.py", line 56, in forward
    x = self.pointwise(x)
  File "/public/dengzhijian/miniconda3/envs/dfs/lib/python3.6/site-packages/torch/nn/modules/module.py", line 727, in _call_impl
    result = self.forward(*input, **kwargs)
  File "/public/dengzhijian/miniconda3/envs/dfs/lib/python3.6/site-packages/torch/nn/modules/conv.py", line 423, in forward
    return self._conv_forward(input, self.weight)
  File "/public/dengzhijian/miniconda3/envs/dfs/lib/python3.6/site-packages/torch/nn/modules/conv.py", line 420, in _conv_forward
    self.padding, self.dilation, self.groups)
RuntimeError: CUDA out of memory. Tried to allocate 66.00 MiB (GPU 0; 10.76 GiB total capacity; 9.70 GiB already allocated; 47.12 MiB free; 9.82 GiB reserved in total by PyTorch)
/var/spool/slurmd/job78104/slurm_script: line 12: data: command not found
